### 错误与异常

---

#### 语法错误

语法分析器指出错误行，并且在检测到错误的位置前面显示一个小“箭头”。

```python

while True print 'Hello world.'

# File "<stdin>", line 1, in ?
#    while True print 'Hello world.'
#              ^

# SyntaxError: invalid syntax

```

#### 异常

即使一条语句或表达式在语法上是正确的，当试图执行它时也可能会引发错误。运行时检测到的错误称为异常。

```python
>>> 10 * (1 / 0)
Traceback (most recent call last):
  File "<stdin>", line 1, in <module>
ZeroDivisionError: integer division or modulo by zero

>>> 4 + spam * 3
Traceback (most recent call last):
  File "<stdin>", line 1, in <module>
NameError: name 'spam' is not defined

```

异常类型做为错误信息的一部分显示出来：示例中的异常分别为零除错误（ZeroDivisionError），命名错误（NameError）。
打印错误信息时，异常类型作为异常内置名显示。

#### 异常处理语句 try..except...else...finally

```python
while True:
    try:
        x = int(raw_input('Please enter a number:'))
        break
    except ValueError:
        print 'Oops! That was no valid number, Try again....'

```

try语句按如下方式工作:
> * 首先，执行try子句（try和except关键字之间的部分）
> * 如果没有发生异常，except子句在try语句执行完毕后就被忽略。
> * 如果在try子句执行过程中发生了异常，那么该子句其余的部分会被忽略。如果异常匹配于except关键字后面指定的异常类型就执行对应的except子句。然后继续执行try语句之后的代码。
> * 如果发生了一个异常，在except子句中没有与之匹配的分支，它就会传递到上一级try语句中。如果最终仍找不到对应的处理语句，它就会成为一个未处理异常，终止程序运行，显示提示信息。

一个try语句可能包含多个except子句，分别处理不同的异常。

```python
def div(a, b):
    try:
        print a / b
        print 'cotinue'
    except ZeroDivisionError:
        print 'Error: b should not be 0 !'
    except Exception as e:
        print 'Unexpexted Error: {}'.format(e)
    else:
        print 'Run into else only when everything goes well.'
    finally:
        print 'Always run into finally block.'

div(2, 0)
div(2, 'bad type')
div(1.0, 2)

# 一个except子句可以在括号中列出多个异常的名字。

try:
    pass
except (RuntimeError, TypeError, NameError):
    pass

# 最后一个except子句可以省略异常名称，以作为通配符使用。

import sys

try:
    f = open('filename')
    s = f.readline()
    i = int(s.strip())
except IOError as e:
    print 'I/O error({0}): {1}'.format(e.errno, e.strerror)
except ValueError:
    print 'Could not convert data to an integer.'
except:
    logging.exception('Exception caught!')
    error_type, error_value, trace_back = sys.exc_info()
    print 'Unexcepted error:', sys.exc_info()[0]
    raise

# try...except语句可以带有一个else子句，该子句只能出现在所有except子句之后。
# 当try语句没有抛出异常时，需要执行一些代码，可以使用这个子句。

for arg in sys.argv[1:]:
    try:
        f = open(arg, 'r')
    except IOError:
        pass
    else:
        f.close()

```

#### 抛出异常

```python
raise NameError('Error!')

try:
    raise NameError('NameError')
except NameError:
    print 'An exception flew by!'
    raise

```

#### 用户自定义异常

```python
class DError(Exception):

    def __init__(self, msg):
        self.msg = msg

    def __str__(self):
        return repr(self.msg)

try:
    raise DError('Error message')
except DError as e:
    print 'Exception occurred, msg: {}'.format(e.msg)

```

如果一个新创建的模块中需要抛出几种不同的错误时，一个通常的做法是为该模块定义一个异常基类，然后针对
不同的错误类型派生出对应的异常子类。

```python
class Error(Exception):
    """ Base class for exceptions in this module. """
    pass


class InputError(Error):
    """
    Exception raise for errors in the input.

    Attributes:
        expression -- input expression in which the error occurred
        message  -- explanation of the error
    """

    def __init__(self, expression, message):
        self.expression = expression
        self.message = message


class TransitionError(Error):
    """
    Raised when an operation attempts a state transition that's not allowed.

    Attributes:
        previous -- state at beginning of transiton
        next -- attempted new state
        message -- explanation of why the specific transition is not allowed
    """

    def __init__(self, previous, next, message):
        self.previous = previous
        self.next = next
        self.message = message

```

#### 定义清理行为

try语句还有一个可选的子句，目的在于定义一个在任何情况下都一定执行的功能。

```python
try:
    raise KeyboardInterrupt
finally:
    print 'executing finally clause'

```
